<?xml version="1.0" ?>
<!-- =================================================================================== -->
<!-- |    This document was autogenerated by xacro from /home/andrewgillies/catkin_ws/src/reachy_description/reachy.URDF.xacro | -->
<!-- |    EDITING THIS FILE BY HAND IS NOT RECOMMENDED                                 | -->
<!-- =================================================================================== -->
<robot name="reachy">

    <link name="world" />
    <joint name="world_joint" type="fixed">
        <origin rpy="0 0 0" xyz="0 0 0" />
        <parent link="world" />
        <child link="pedestal" />
    </joint>

    <!-- Torso Link -->
    <link name="pedestal" />
    <link name="torso">
        
<inertial>
            <origin rpy="0.0 0.0 0.0" xyz="0.0 0.019 -0.009" />
            <mass value="0.527" />
    <inertia ixx="0.1" ixy="0.0" ixz="0.0" iyy="0.1" iyz="0.0" izz="0.1"/>
        </inertial>

        <visual name="">
            <origin rpy="0.0 0.0 0.0" xyz="0.0 0.0 0.0" />
            <geometry>
                <mesh filename="package://reachy_description/meshes/torso.dae" />
            </geometry>
        </visual>
        <collision>
            <origin rpy="0 0.05 0" xyz="0 0 -0.1" />
            <geometry>
                <box size="0.11 0.2 0.32" />
            </geometry>
        </collision>
    </link>
    <!-- Head Links -->
    <!-- Right Arm Links -->
    <link name="r_shoulder">
        
<inertial>
            <origin rpy="1.57 1.57 0.0" xyz="-0.016 0.036 0.0" />
            <mass value="0.053" />
    <inertia ixx="0.1" ixy="0.0" ixz="0.0" iyy="0.1" iyz="0.0" izz="0.1"/>
        </inertial>

        <visual name="">
            <origin rpy="1.57 1.57 0.0" xyz="0.0 0.04 0.0" />
            <geometry>
                <mesh filename="package://reachy_description/meshes/shoulder.dae" />
            </geometry>
        </visual>
        <collision>
            <origin rpy="1.57 1.57 0.0" xyz="0.0 0.04 0.0" />
            <geometry>
                <cylinder length="0.09" radius="0.035" />
            </geometry>
        </collision>
    </link>
    <link name="r_shoulder_x">
        
<inertial>
            <origin rpy="0.0 0.0 0.0" xyz="-0.0 0.0 -0.019" />
            <mass value="0.158" />
    <inertia ixx="0.1" ixy="0.0" ixz="0.0" iyy="0.1" iyz="0.0" izz="0.1"/>
        </inertial>

        <visual name="">
            <origin rpy="0.0 0.0 0.0" xyz="0.0 0.0 0.0" />
            <geometry>
                <mesh filename="package://reachy_description/meshes/shoulder_x.dae" />
            </geometry>
        </visual>
        <collision>
            <origin rpy="0.0 0.0 0.0" xyz="0 0 -0.02" />
            <geometry>
                <cylinder length="0.04" radius="0.035" />
            </geometry>
        </collision>
    </link>
    <link name="r_upper_arm">
        
<inertial>
            <origin rpy="0.0 0.0 0.0" xyz="-0.004 0.0 -0.1426" />
            <mass value="0.430" />
    <inertia ixx="0.1" ixy="0.0" ixz="0.0" iyy="0.1" iyz="0.0" izz="0.1"/>
        </inertial>

        <visual name="">
            <origin rpy="0.0 0.0 0.0" xyz="0.0 0.0 -0.0526" />
            <geometry>
                <mesh filename="package://reachy_description/meshes/upper_arm.dae" />
            </geometry>
        </visual>
        <collision>
            <origin rpy="0.0 0.0 0.0" xyz="0.0 0.0 -0.16" />
            <geometry>
                <cylinder length="0.25" radius="0.04" />
            </geometry>
        </collision>
    </link>
    <link name="r_forearm">
        
<inertial>
            <origin rpy="0.0 0.0 0.0" xyz="-0.008 0.0 -0.058" />
            <mass value="0.162" />
    <inertia ixx="0.1" ixy="0.0" ixz="0.0" iyy="0.1" iyz="0.0" izz="0.1"/>
        </inertial>

        <visual name="">
            <origin rpy="0.0 0.0 0.0" xyz="0.0 0.0 0.0" />
            <geometry>
                <mesh filename="package://reachy_description/meshes/forearm.dae" />
            </geometry>
        </visual>
        <collision>
            <origin rpy="0.0 0.0 0.0" xyz="0.0 0.0 -0.058" />
            <geometry>
                <cylinder length="0.09" radius="0.04" />
            </geometry>
        </collision>
    </link>
    <link name="r_wrist">
        
<inertial>
            <origin rpy="0.0 0.0 0.0" xyz="0.0 0.0 -0.193" />
            <mass value="0.197" />
    <inertia ixx="0.1" ixy="0.0" ixz="0.0" iyy="0.1" iyz="0.0" izz="0.1"/>
        </inertial>

        <visual name="">
            <origin rpy="0.0 0.0 0.0" xyz="0.0 0.0 -0.100" />
            <geometry>
                <mesh filename="package://reachy_description/meshes/wrist.dae" />
            </geometry>
        </visual>
        <collision>
            <origin rpy="0.0 0.0 0.0" xyz="0.0 0.0 -0.18" />
            <geometry>
                <cylinder length="0.14" radius="0.035" />
            </geometry>
        </collision>
    </link>
    <link name="r_wrist2hand">
        
<inertial>
            <origin rpy="0.0 0.0 0.0" xyz="0.0 0.0 0.014" />
            <mass value="0.01" />
    <inertia ixx="0.1" ixy="0.0" ixz="0.0" iyy="0.1" iyz="0.0" izz="0.1"/>
        </inertial>

        <visual name="">
            <origin rpy="0.0 0.0 0.0" xyz="0.0 0.0 0.0" />
            <geometry>
                <mesh filename="package://reachy_description/meshes/wrist2hand.dae" />
            </geometry>
        </visual>
        <collision>
            <origin rpy="0.0 0.0 0.0" xyz="0.0 0.0 -0.03" />
            <geometry>
                <cylinder length="0.06" radius="0.03" />
            </geometry>
        </collision>
    </link>
    <link name="r_gripper_thumb">
        
<inertial>
            <origin rpy="0.0 1.57 0.0" xyz="0.032 -0.008 0.0" />
            <mass value="0.173" />
    <inertia ixx="0.1" ixy="0.0" ixz="0.0" iyy="0.1" iyz="0.0" izz="0.1"/>
        </inertial>

        <visual name="">
            <origin rpy="0.0 1.57 0.0" xyz="0.0 0.0 0.0" />
            <geometry>
                <mesh filename="package://reachy_description/meshes/r_gripper_thumb.dae" />
            </geometry>
        </visual>
        <collision>
            <origin rpy="0.0 1.57 0.0" xyz="0.0 0.02 -0.06" />
            <geometry>
                <box size="0.1 0.012 0.035" />
            </geometry>
        </collision>
    </link>
    <link name="r_gripper_finger">
        
<inertial>
            <origin rpy="0.0 1.57 0.0" xyz="-0.005 -0.043 -0.0" />
            <mass value="0.035" />
    <inertia ixx="0.1" ixy="0.0" ixz="0.0" iyy="0.1" iyz="0.0" izz="0.1"/>
        </inertial>

        <visual name="">
            <origin rpy="0.0 1.57 0.0" xyz="0.0 0.0 0.0" />
            <geometry>
                <mesh filename="package://reachy_description/meshes/r_gripper_finger.dae" />
            </geometry>
        </visual>
        <collision>
            <origin rpy="0.0 1.57 0.0" xyz="0.0 -0.01 -0.02" />
            <geometry>
                <box size="0.1 0.012 0.035" />
            </geometry>
        </collision>
    </link>
    <link name="right_tip" />
    <!-- Left Arm Links -->
    <link name="l_shoulder">
        
<inertial>
            <origin rpy="-1.57 1.57 0.0" xyz="-0.016 0.044 0.0" />
            <mass value="0.053" />
    <inertia ixx="0.1" ixy="0.0" ixz="0.0" iyy="0.1" iyz="0.0" izz="0.1"/>
        </inertial>

        <visual name="">
            <origin rpy="-1.57 1.57 0.0" xyz="0.0 -0.04 0.0" />
            <geometry>
                <mesh filename="package://reachy_description/meshes/shoulder.dae" />
            </geometry>
        </visual>
        <collision>
            <origin rpy="-1.57 1.57 0.0" xyz="0.0 -0.04 0.0" />
            <geometry>
                <cylinder length="0.09" radius="0.035" />
            </geometry>
        </collision>
    </link>
    <link name="l_shoulder_x">
        
<inertial>
            <origin rpy="0.0 0.0 0.0" xyz="0.0 0.0 -0.019" />
            <mass value="0.158" />
    <inertia ixx="0.1" ixy="0.0" ixz="0.0" iyy="0.1" iyz="0.0" izz="0.1"/>
        </inertial>

        <visual name="">
            <origin rpy="0.0 0.0 0.0" xyz="0.0 0.0 0.0" />
            <geometry>
                <mesh filename="package://reachy_description/meshes/shoulder_x.dae" />
            </geometry>
        </visual>
        <collision>
            <origin rpy="0.0 0.0 0.0" xyz="0 0 -0.02" />
            <geometry>
                <cylinder length="0.04" radius="0.035" />
            </geometry>
        </collision>
    </link>
    <link name="l_upper_arm">
        
<inertial>
            <origin rpy="0.0 0.0 0.0" xyz="-0.004 0.0 -0.1426" />
            <mass value="0.430" />
    <inertia ixx="0.1" ixy="0.0" ixz="0.0" iyy="0.1" iyz="0.0" izz="0.1"/>
        </inertial>

        <visual name="">
            <origin rpy="0.0 0.0 0.0" xyz="0.0 0.0 -0.0526" />
            <geometry>
                <mesh filename="package://reachy_description/meshes/upper_arm.dae" />
            </geometry>
        </visual>
        <collision>
            <origin rpy="0.0 0.0 0.0" xyz="0.0 0.0 -0.16" />
            <geometry>
                <cylinder length="0.25" radius="0.04" />
            </geometry>
        </collision>
    </link>
    <link name="l_forearm">
        
<inertial>
            <origin rpy="0.0 0.0 0.0" xyz="-0.008 0.0 -0.058" />
            <mass value="0.162" />
    <inertia ixx="0.1" ixy="0.0" ixz="0.0" iyy="0.1" iyz="0.0" izz="0.1"/>
        </inertial>

        <visual name="">
            <origin rpy="0.0 0.0 0.0" xyz="0.0 0.0 0.0" />
            <geometry>
                <mesh filename="package://reachy_description/meshes/forearm.dae" />
            </geometry>
        </visual>
        <collision>
            <origin rpy="0.0 0.0 0.0" xyz="0.0 0.0 -0.058" />
            <geometry>
                <cylinder length="0.09" radius="0.04" />
            </geometry>
        </collision>
    </link>
    <link name="l_wrist">
        
<inertial>
            <origin rpy="0.0 0.0 0.0" xyz="0.0 0.0 -0.193" />
            <mass value="0.197" />
    <inertia ixx="0.1" ixy="0.0" ixz="0.0" iyy="0.1" iyz="0.0" izz="0.1"/>
        </inertial>

        <visual name="">
            <origin rpy="0.0 0.0 0.0" xyz="0.0 0.0 -0.1" />
            <geometry>
                <mesh filename="package://reachy_description/meshes/wrist.dae" />
            </geometry>
        </visual>
        <collision>
            <origin rpy="0.0 0.0 0.0" xyz="0.0 0.0 -0.18" />
            <geometry>
                <cylinder length="0.14" radius="0.035" />
            </geometry>
        </collision>
    </link>
    <link name="l_wrist2hand">
        
<inertial>
            <origin rpy="0.0 0.0 0.0" xyz="0.0 0.0 0.014" />
            <mass value="0.01" />
    <inertia ixx="0.1" ixy="0.0" ixz="0.0" iyy="0.1" iyz="0.0" izz="0.1"/>
        </inertial>

        <visual name="">
            <origin rpy="0.0 0.0 0.0" xyz="0.0 0.0 0.0" />
            <geometry>
                <mesh filename="package://reachy_description/meshes/wrist2hand.dae" />
            </geometry>
        </visual>
        <collision>
            <origin rpy="0.0 0.0 0.0" xyz="0.0 0.0 -0.03" />
            <geometry>
                <cylinder length="0.06" radius="0.03" />
            </geometry>
        </collision>
    </link>
    <link name="l_gripper_thumb">
        
<inertial>
            <origin rpy="0.0 1.57 0.0" xyz="0.032 0.008 0.0" />
            <mass value="0.173" />
    <inertia ixx="0.1" ixy="0.0" ixz="0.0" iyy="0.1" iyz="0.0" izz="0.1"/>
        </inertial>

        <visual name="">
            <origin rpy="0.0 1.57 0.0" xyz="0.0 0.0 0.0" />
            <geometry>
                <mesh filename="package://reachy_description/meshes/l_gripper_thumb.dae" />
            </geometry>
        </visual>
        <collision>
            <origin rpy="0.0 1.57 0.0" xyz="0.0 -0.02 -0.06" />
            <geometry>
                <box size="0.1 0.012 0.035" />
            </geometry>
        </collision>
    </link>
    <link name="l_gripper_finger">
        
<inertial>
            <origin rpy="0.0 1.57 0.0" xyz="0.005 -0.043 0.0" />
            <mass value="0.035" />
    <inertia ixx="0.1" ixy="0.0" ixz="0.0" iyy="0.1" iyz="0.0" izz="0.1"/>
        </inertial>

        <visual name="">
            <origin rpy="0.0 1.57 0.0" xyz="0.0 0.0 0.0" />
            <geometry>
                <mesh filename="package://reachy_description/meshes/l_gripper_finger.dae" />
            </geometry>
        </visual>
        <collision>
            <origin rpy="0.0 1.57 0.0" xyz="0.0 0.01 -0.02" />
            <geometry>
                <box size="0.1 0.012 0.035" />
            </geometry>
        </collision>
    </link>
    <link name="left_tip" />
    <!-- Head and Torso joints -->
    <joint name="pedestal" type="fixed">
        <origin rpy="0 0 0" xyz="0 0 1" />
        <parent link="pedestal" />
        <child link="torso" />
    </joint>
    <!-- Right Arm joint -->
    <joint name="r_shoulder_pitch" type="revolute">
        <origin rpy="0.0 0.0 0.0" xyz="0.0 -0.19 0.0" />
        <parent link="torso" />
        <child link="r_shoulder" />
        <axis xyz="0 1 0" />
        <limit effort="10.0" lower="-2.618" upper="1.57" velocity="100.0" />
        <dynamics damping="0.7"/>
    </joint>
    <joint name="r_shoulder_roll" type="revolute">
        <origin rpy="0.0 0.0 0.0" xyz="0 0 0" />
        <parent link="r_shoulder" />
        <child link="r_shoulder_x" />
        <axis xyz="1 0 0" />
        <limit effort="100.0" lower="-3.14" upper="0.174" velocity="100.0" />
    </joint>
    <joint name="r_arm_yaw" type="revolute">
        <origin rpy="0.0 0.0 0.0" xyz="0 0 0" />
        <parent link="r_shoulder_x" />
        <child link="r_upper_arm" />
        <axis xyz="0 0 1" />
        <limit effort="100.0" lower="-1.57" upper="1.57" velocity="100.0" />
        <dynamics damping="0.7"/>
    </joint>
    <joint name="r_elbow_pitch" type="revolute">
        <origin rpy="0.0 0.0 0.0" xyz="0 0 -0.28" />
        <parent link="r_upper_arm" />
        <child link="r_forearm" />
        <axis xyz="0 1 0" />
        <limit effort="100.0" lower="-2.182" upper="0" velocity="100.0" />
    </joint>
    <joint name="r_forearm_yaw" type="revolute">
        <origin rpy="0.0 0.0 0.0" xyz="0 0 0" />
        <parent link="r_forearm" />
        <child link="r_wrist" />
        <axis xyz="0 0 1" />
        <limit effort="100.0" lower="-1.745" upper="1.745" velocity="100.0" />
        <dynamics damping="0.7"/>
    </joint>
    <joint name="r_wrist_pitch" type="revolute">
        <origin rpy="0.0 0.0 0.0" xyz="0 0 -0.25" />
        <parent link="r_wrist" />
        <child link="r_wrist2hand" />
        <axis xyz="0 1 0" />
        <limit effort="100.0" lower="-0.785" upper="0.785" velocity="100.0" />
    </joint>
    <joint name="r_wrist_roll" type="revolute">
        <origin rpy="0.0 0.0 0.0" xyz="0 0 -0.0325" />
        <parent link="r_wrist2hand" />
        <child link="r_gripper_thumb" />
        <axis xyz="1 0 0" />
        <limit effort="100.0" lower="-0.785" upper="0.785" velocity="100.0" />
        <dynamics damping="0.7"/>
    </joint>
    <joint name="r_gripper" type="fixed">
        <origin rpy="0.0 0.0 0.0" xyz="0.0 -0.037 -0.03998" />
        <parent link="r_gripper_thumb" />
        <child link="r_gripper_finger" />
        <axis xyz="1 0 0" />
        <limit effort="100.0" lower="-1.2" upper="0.35" velocity="100.0" />
    </joint>
    <joint name="r_tip" type="fixed">
        <origin rpy="0 0 0" xyz="0 -0.012 -0.085" />
        <parent link="r_gripper_thumb" />
        <child link="right_tip" />
    </joint>
    <joint name="l_shoulder_pitch" type="revolute">
        <origin rpy="0.0 0.0 0.0" xyz="0.0 0.19 0.0" />
        <parent link="torso" />
        <child link="l_shoulder" />
        <axis xyz="0 1 0" />
        <limit effort="100.0" lower="-2.618" upper="1.57" velocity="100.0" />
        <dynamics damping="0.7"/>
    </joint>
    <joint name="l_shoulder_roll" type="revolute">
        <origin rpy="0.0 0.0 0.0" xyz="0 0 0" />
        <parent link="l_shoulder" />
        <child link="l_shoulder_x" />
        <axis xyz="1 0 0" />
        <limit effort="100.0" lower="-0.174" upper="3.14" velocity="100.0" />
    </joint>
    <joint name="l_arm_yaw" type="revolute">
        <origin rpy="0.0 0.0 0.0" xyz="0 0 0" />
        <parent link="l_shoulder_x" />
        <child link="l_upper_arm" />
        <axis xyz="0 0 1" />
        <limit effort="100.0" lower="-1.57" upper="1.57" velocity="100.0" />
        <dynamics damping="0.7"/>
    </joint>
    <joint name="l_elbow_pitch" type="revolute">
        <origin rpy="0.0 0.0 0.0" xyz="0 0 -0.28" />
        <parent link="l_upper_arm" />
        <child link="l_forearm" />
        <axis xyz="0 1 0" />
        <limit effort="100.0" lower="-2.182" upper="0" velocity="100.0" />
    </joint>
    <joint name="l_forearm_yaw" type="revolute">
        <origin rpy="0.0 0.0 0.0" xyz="0 0 0" />
        <parent link="l_forearm" />
        <child link="l_wrist" />
        <axis xyz="0 0 1" />
        <limit effort="100.0" lower="-1.745" upper="1.745" velocity="100.0" />
        <dynamics damping="0.7"/>
    </joint>
    <joint name="l_wrist_pitch" type="revolute">
        <origin rpy="0.0 0.0 0.0" xyz="0 0 -0.25" />
        <parent link="l_wrist" />
        <child link="l_wrist2hand" />
        <axis xyz="0 1 0" />
        <limit effort="100.0" lower="-0.785" upper="0.785" velocity="100.0" />
    </joint>
    <joint name="l_wrist_roll" type="revolute">
        <origin rpy="0.0 0.0 0.0" xyz="0 0 -0.0325" />
        <parent link="l_wrist2hand" />
        <child link="l_gripper_thumb" />
        <axis xyz="1 0 0" />
        <limit effort="100.0" lower="-0.785" upper="0.785" velocity="100.0" />
        <dynamics damping="0.7"/>
    </joint>
    <joint name="l_gripper" type="fixed">
        <origin rpy="0.0 0.0 0.0" xyz="0.0 0.037 -0.03998" />
        <parent link="l_gripper_thumb" />
        <child link="l_gripper_finger" />
        <axis xyz="1 0 0" />
        <limit effort="100.0" lower="-0.35" upper="1.2" velocity="100.0" />
    </joint>
    <joint name="l_tip" type="fixed">
        <origin rpy="0 0 0" xyz="0 0.012 -0.085" />
        <parent link="l_gripper_thumb" />
        <child link="left_tip" />
    </joint>
    <!-- Head joint... -->
    <!-- ...with a fixed joint -->
    <!--
<joint name="torso2head" type="fixed">
    <origin xyz="0.015 0.0 0.095" rpy="0 0.174 0" />
    <parent link="torso" />
    <child link="head" />
</joint>
-->
    
<transmission name="trans_r_shoulder_pitch">
        <type>transmission_interface/SimpleTransmission</type>
        <joint name="r_shoulder_pitch">
            <hardwareInterface>hardware_interface/EffortJointInterface</hardwareInterface>
        </joint>
        <actuator name="r_shoulder_pitch_motor">
            <hardwareInterface>hardware_interface/EffortJointInterface</hardwareInterface>
            <mechanicalReduction>1</mechanicalReduction>
        </actuator>
    </transmission>
    <transmission name="trans_r_shoulder_roll">
        <type>transmission_interface/SimpleTransmission</type>
        <joint name="r_shoulder_roll">
            <hardwareInterface>hardware_interface/EffortJointInterface</hardwareInterface>
        </joint>
        <actuator name="r_shoulder_roll_motor">
            <hardwareInterface>hardware_interface/EffortJointInterface</hardwareInterface>
            <mechanicalReduction>1</mechanicalReduction>
        </actuator>
    </transmission>
    <transmission name="trans_r_arm_yaw">
        <type>transmission_interface/SimpleTransmission</type>
        <joint name="r_arm_yaw">
            <hardwareInterface>hardware_interface/EffortJointInterface</hardwareInterface>
        </joint>
        <actuator name="r_arm_yaw_motor">
            <hardwareInterface>hardware_interface/EffortJointInterface</hardwareInterface>
            <mechanicalReduction>1</mechanicalReduction>
        </actuator>
    </transmission>
    <transmission name="trans_r_elbow_pitch">
        <type>transmission_interface/SimpleTransmission</type>
        <joint name="r_elbow_pitch">
            <hardwareInterface>hardware_interface/EffortJointInterface</hardwareInterface>
        </joint>
        <actuator name="r_elbow_pitch_motor">
            <hardwareInterface>hardware_interface/EffortJointInterface</hardwareInterface>
            <mechanicalReduction>1</mechanicalReduction>
        </actuator>
    </transmission>
    <transmission name="trans_r_forearm_yaw">
        <type>transmission_interface/SimpleTransmission</type>
        <joint name="r_forearm_yaw">
            <hardwareInterface>hardware_interface/EffortJointInterface</hardwareInterface>
        </joint>
        <actuator name="r_forearm_yaw_motor">
            <hardwareInterface>hardware_interface/EffortJointInterface</hardwareInterface>
            <mechanicalReduction>1</mechanicalReduction>
        </actuator>
    </transmission>
    <transmission name="trans_r_wrist_pitch">
        <type>transmission_interface/SimpleTransmission</type>
        <joint name="r_wrist_pitch">
            <hardwareInterface>hardware_interface/EffortJointInterface</hardwareInterface>
        </joint>
        <actuator name="r_wrist_pitch_motor">
            <hardwareInterface>hardware_interface/EffortJointInterface</hardwareInterface>
            <mechanicalReduction>1</mechanicalReduction>
        </actuator>
    </transmission>
    <transmission name="trans_r_wrist_roll">
        <type>transmission_interface/SimpleTransmission</type>
        <joint name="r_wrist_roll">
            <hardwareInterface>hardware_interface/EffortJointInterface</hardwareInterface>
        </joint>
        <actuator name="r_wrist_roll_motor">
            <hardwareInterface>hardware_interface/EffortJointInterface</hardwareInterface>
            <mechanicalReduction>1</mechanicalReduction>
        </actuator>
    </transmission>

    <transmission name="trans_l_shoulder_pitch">
        <type>transmission_interface/SimpleTransmission</type>
        <joint name="l_shoulder_pitch">
            <hardwareInterface>hardware_interface/EffortJointInterface</hardwareInterface>
        </joint>
        <actuator name="l_shoulder_pitch_motor">
            <hardwareInterface>hardware_interface/EffortJointInterface</hardwareInterface>
            <mechanicalReduction>1</mechanicalReduction>
        </actuator>
    </transmission>
    <transmission name="trans_l_shoulder_roll">
        <type>transmission_interface/SimpleTransmission</type>
        <joint name="l_shoulder_roll">
            <hardwareInterface>hardware_interface/EffortJointInterface</hardwareInterface>
        </joint>
        <actuator name="l_shoulder_roll_motor">
            <hardwareInterface>hardware_interface/EffortJointInterface</hardwareInterface>
            <mechanicalReduction>1</mechanicalReduction>
        </actuator>
    </transmission>
    <transmission name="trans_l_arm_yaw">
        <type>transmission_interface/SimpleTransmission</type>
        <joint name="l_arm_yaw">
            <hardwareInterface>hardware_interface/EffortJointInterface</hardwareInterface>
        </joint>
        <actuator name="l_arm_yaw_motor">
            <hardwareInterface>hardware_interface/EffortJointInterface</hardwareInterface>
            <mechanicalReduction>1</mechanicalReduction>
        </actuator>
    </transmission>
    <transmission name="trans_l_elbow_pitch">
        <type>transmission_interface/SimpleTransmission</type>
        <joint name="l_elbow_pitch">
            <hardwareInterface>hardware_interface/EffortJointInterface</hardwareInterface>
        </joint>
        <actuator name="l_elbow_pitch_motor">
            <hardwareInterface>hardware_interface/EffortJointInterface</hardwareInterface>
            <mechanicalReduction>1</mechanicalReduction>
        </actuator>
    </transmission>
    <transmission name="trans_l_forearm_yaw">
        <type>transmission_interface/SimpleTransmission</type>
        <joint name="l_forearm_yaw">
            <hardwareInterface>hardware_interface/EffortJointInterface</hardwareInterface>
        </joint>
        <actuator name="l_forearm_yaw_motor">
            <hardwareInterface>hardware_interface/EffortJointInterface</hardwareInterface>
            <mechanicalReduction>1</mechanicalReduction>
        </actuator>
    </transmission>
    <transmission name="trans_l_wrist_pitch">
        <type>transmission_interface/SimpleTransmission</type>
        <joint name="l_wrist_pitch">
            <hardwareInterface>hardware_interface/EffortJointInterface</hardwareInterface>
        </joint>
        <actuator name="l_wrist_pitch_motor">
            <hardwareInterface>hardware_interface/EffortJointInterface</hardwareInterface>
            <mechanicalReduction>1</mechanicalReduction>
        </actuator>
    </transmission>
    <transmission name="trans_l_wrist_roll">
        <type>transmission_interface/SimpleTransmission</type>
        <joint name="l_wrist_roll">
            <hardwareInterface>hardware_interface/EffortJointInterface</hardwareInterface>
        </joint>
        <actuator name="l_wrist_roll_motor">
            <hardwareInterface>hardware_interface/EffortJointInterface</hardwareInterface>
            <mechanicalReduction>1</mechanicalReduction>
        </actuator>
    </transmission>
    <gazebo>
        <plugin name="gazebo_ros_control" filename="libgazebo_ros_control.so">
            <robotNamespace>/</robotNamespace>
        </plugin>
    </gazebo>
</robot>